test "Test with expected exception without errors" {

	assert.throwsException { 
		const x = null
		x.foo()
	}
}