
test "testWithExpectedExceptionWithErrors" {

	assert.throwsException { 4 }
}